<?xml version="1.0" ?>
<!-- =================================================================================== -->
<!-- |    This document was autogenerated by xacro from seven_dof_arm.xacro            | -->
<!-- |    EDITING THIS FILE BY HAND IS NOT RECOMMENDED                                 | -->
<!-- =================================================================================== -->
<robot name="seven_dof_arm" xmlns:xacro="http://www.ros.org/wiki/xacro">
  <material name="Black">
    <color rgba="0 0 0 1"/>
  </material>
  <material name="Red">
    <color rgba="1 0 0 1"/>
  </material>
  <material name="White">
    <color rgba="1 1 1 1"/>
  </material>
  <!--
  <xacro:base name="base"/>
  <xacro:arm parent="base"/>
  <xacro:gripper parent="tool"/>
-->
  <!--
	////////////////////////////////////////////////////////////
	////////////////////////////////////////////////////////////
-->
  <joint name="bottom_joint" type="fixed">
    <origin rpy="0 0 0" xyz="0 0 0"/>
    <parent link="base_link"/>
    <child link="bottom_link"/>
  </joint>
  <link name="bottom_link">
    <visual>
      <origin rpy="0 0 0" xyz="0 0 -0.04"/>
      <geometry>
        <box size="1 1 0.02"/>
      </geometry>
    </visual>
    <collision>
      <origin xyz="0 0 -0.04"/>
      <geometry>
        <box size="1 1 0.02"/>
      </geometry>
    </collision>
  </link>
  <gazebo reference="bottom_link">
    <material>Gazebo/White</material>
  </gazebo>
  <!--
	////////////////////////////////////////////////////////////
	////////////////////////////////////////////////////////////
-->
  <link name="base_link">
    <visual>
      <origin rpy="1.57079632699 0 0" xyz="0 0 0"/>
      <geometry>
        <box size="0.1 0.1 0.1"/>
      </geometry>
    </visual>
    <collision>
      <origin rpy="1.57079632699 0 0" xyz="0 0 0"/>
      <geometry>
        <box size="0.1 0.1 0.1"/>
      </geometry>
    </collision>
    <inertial>
      <mass value="1"/>
      <inertia ixx="1.0" ixy="0.0" ixz="0.0" iyy="1.0" iyz="0.0" izz="1.0"/>
    </inertial>
  </link>
  <gazebo reference="bottom_link">
    <material>Gazebo/White</material>
  </gazebo>
  <!--
	////////////////////////////////////////////////////////////
	////////////////////////////////////////////////////////////
-->
  <joint name="shoulder_pan_joint" type="revolute">
    <parent link="base_link"/>
    <child link="shoulder_pan_link"/>
    <origin rpy="0 1.57079632699 0.0" xyz="0 0 0.05"/>
    <axis xyz="-1 0 0"/>
    <limit effort="300" lower="-2.61799" upper="1.98394" velocity="20"/>
    <dynamics damping="50" friction="1"/>
  </joint>
  <!--
	////////////////////////////////////////////////////////////
	////////////////////////////////////////////////////////////
-->
  <link name="shoulder_pan_link">
    <visual>
      <origin rpy="0 1.57079632699 0" xyz="0 0 0"/>
      <geometry>
        <cylinder length="0.08" radius="0.04"/>
      </geometry>
      <material name="Red"/>
    </visual>
    <collision>
      <origin rpy="0 1.57079632699 0" xyz="0 0 0"/>
      <geometry>
        <cylinder length="0.08" radius="0.04"/>
      </geometry>
    </collision>
    <inertial>
      <mass value="1"/>
      <inertia ixx="1.0" ixy="0.0" ixz="0.0" iyy="1.0" iyz="0.0" izz="1.0"/>
    </inertial>
  </link>
  <gazebo reference="shoulder_pan_link">
    <material>Gazebo/Red</material>
  </gazebo>
  <!--
	////////////////////////////////////////////////////////////
	////////////////////////////////////////////////////////////
-->
  <joint name="shoulder_pitch_joint" type="revolute">
    <parent link="shoulder_pan_link"/>
    <child link="shoulder_pitch_link"/>
    <origin rpy="-1.57079632699 0 1.57079632699" xyz="-0.041 0.0021 0.0"/>
    <axis xyz="1 0 0"/>
    <limit effort="300" lower="-1.1996" upper="1.8994" velocity="1"/>
    <dynamics dapming="50" friction="1"/>
  </joint>
  <!--
	////////////////////////////////////////////////////////////
	////////////////////////////////////////////////////////////
-->
  <link name="shoulder_pitch_link">
    <visual>
      <origin rpy="0 1.57079632699 0" xyz="-0.002 0 0.04"/>
      <geometry>
        <box size="0.14 0.04 0.04"/>
      </geometry>
      <material name="White"/>
    </visual>
    <collision>
      <origin rpy="0 1.57079632699 0" xyz="-0.002 0 0.04"/>
      <geometry>
        <box size="0.14 0.04 0.04"/>
      </geometry>
    </collision>
    <inertial>
      <mass value="1"/>
      <inertia ixx="1.0" ixy="0.0" ixz="0.0" iyy="1.0" iyz="0.0" izz="1.0"/>
    </inertial>
  </link>
  <gazebo reference="shoulder_pitch_link">
    <material>Gazebo/White</material>
  </gazebo>
  <!--
	////////////////////////////////////////////////////////////
	////////////////////////////////////////////////////////////
-->
  <joint name="elbow_roll_joint" type="revolute">
    <parent link="shoulder_pitch_link"/>
    <child link="elbow_roll_link"/>
    <origin rpy="3.14159265399 1.57079632699 0" xyz="-0.002 0 0.1206"/>
    <axis xyz="-1 0 0"/>
    <limit effort="300" lower="-2.61799" upper="0.70563" velocity="1"/>
    <dynamics damping="50" friction="1"/>
  </joint>
  <!--
	////////////////////////////////////////////////////////////
	////////////////////////////////////////////////////////////
-->
  <link name="elbow_roll_link">
    <visual>
      <origin rpy="0 1.57079632699 0" xyz="-0.015 0.0 -0.0"/>
      <geometry>
        <cylinder length="0.04" radius="0.02"/>
      </geometry>
      <material name="Black"/>
    </visual>
    <collision>
      <origin rpy="0 1.57079632699 0" xyz="-0.015 0.0 -0.0"/>
      <geometry>
        <cylinder length="0.04" radius="0.02"/>
      </geometry>
    </collision>
    <inertial>
      <mass value="1"/>
      <inertia ixx="1.0" ixy="0.0" ixz="0.0" iyy="1.0" iyz="0.0" izz="1.0"/>
    </inertial>
  </link>
  <gazebo reference="elbow_roll_link">
    <material>Gazebo/Black</material>
  </gazebo>
  <!--
	////////////////////////////////////////////////////////////
	////////////////////////////////////////////////////////////
-->
  <joint name="elbow_pitch_joint" type="revolute">
    <parent link="elbow_roll_link"/>
    <child link="elbow_pitch_link"/>
    <!-- <origin xyz="-0.035 0 0.0" rpy="0.055 ${M_PI/2} 0"/> -->
    <origin rpy="3.14159265399 1.57079632699 0" xyz="-0.035 0 0.0"/>
    <axis xyz="1 0 0"/>
    <limit effort="300" lower="-1.59534" upper="1.9328" velocity="1"/>
    <dynamics damping="50" friction="1"/>
  </joint>
  <!--
	////////////////////////////////////////////////////////////
	////////////////////////////////////////////////////////////
-->
  <link name="elbow_pitch_link">
    <visual>
      <origin rpy="0 1.57079632699 0" xyz="0.0 0.0 -0.12"/>
      <geometry>
        <box size="0.22 0.04 0.04"/>
      </geometry>
      <material name="Red"/>
    </visual>
    <collision>
      <origin rpy="0 1.57079632699 0" xyz="0 0 -0.12"/>
      <geometry>
        <box size="0.22 0.04 0.04"/>
      </geometry>
    </collision>
    <inertial>
      <mass value="1"/>
      <inertia ixx="1.0" ixy="0.0" ixz="0.0" iyy="1.0" iyz="0.0" izz="1.0"/>
    </inertial>
  </link>
  <gazebo reference="elbow_pitch_link">
    <material>Gazebo/Red</material>
  </gazebo>
  <!--
	////////////////////////////////////////////////////////////
	////////////////////////////////////////////////////////////
-->
  <joint name="wrist_roll_joint" type="revolute">
    <parent link="elbow_pitch_link"/>
    <child link="wrist_roll_link"/>
    <origin rpy="0 1.57079632699 3.14159265399" xyz="0.0 0.0081 -0.248"/>
    <axis xyz="1 0 0"/>
    <limit effort="300" lower="-2.61799" upper="2.61288" velocity="1"/>
    <dynamics damping="50" friction="1"/>
  </joint>
  <!--
	////////////////////////////////////////////////////////////
	////////////////////////////////////////////////////////////
-->
  <link name="wrist_roll_link">
    <visual>
      <origin rpy="0 1.57079632699 0" xyz="0 0 0"/>
      <geometry>
        <cylinder length="0.04" radius="0.02"/>
      </geometry>
      <material name="Black"/>
    </visual>
    <collision>
      <origin rpy="0 1.57079632699 0" xyz="0 0 0"/>
      <geometry>
        <cylinder length="0.04" radius="0.02"/>
      </geometry>
    </collision>
    <inertial>
      <mass value="1"/>
      <inertia ixx="1.0" ixy="0.0" ixz="0.0" iyy="1.0" iyz="0.0" izz="1.0"/>
    </inertial>
  </link>
  <gazebo reference="wrist_roll_link">
    <material>Gazebo/Black</material>
  </gazebo>
  <!--
	////////////////////////////////////////////////////////////
	////////////////////////////////////////////////////////////
-->
  <joint name="wrist_pitch_joint" type="revolute">
    <parent link="wrist_roll_link"/>
    <child link="wrist_pitch_link"/>
    <origin rpy="0 1.57079632699 0" xyz="0 0 0.0001"/>
    <axis xyz="1 0 0"/>
    <limit effort="300" lower="-1.59534" upper="1.98394" velocity="1"/>
    <dynamics damping="50" friction="1"/>
  </joint>
  <!--
	////////////////////////////////////////////////////////////
	////////////////////////////////////////////////////////////
-->
  <link name="wrist_pitch_link">
    <visual>
      <origin rpy="0 1.57079632699 0" xyz="0 0 0.04"/>
      <geometry>
        <box size="0.06 0.04 0.04"/>
      </geometry>
    </visual>
    <material name="White"/>
    <collision>
      <origin rpy="0 1.57079632699 0" xyz="0 0 0.04"/>
      <geometry>
        <box size="0.06 0.04 0.04"/>
      </geometry>
    </collision>
    <inertial>
      <mass value="1"/>
      <inertia ixx="1.0" ixy="0.0" ixz="0.0" iyy="1.0" iyz="0.0" izz="1.0"/>
    </inertial>
  </link>
  <gazebo reference="wrist_pitch_link">
    <material>Gazebo/Black</material>
  </gazebo>
  <!--
	////////////////////////////////////////////////////////////
	////////////////////////////////////////////////////////////
-->
  <joint name="gripper_roll_joint" type="revolute">
    <parent link="wrist_pitch_link"/>
    <child link="gripper_roll_link"/>
    <origin rpy="4.71238898098 -1.57079632699 0" xyz="0 0 0.08"/>
    <axis xyz="1 0 0"/>
    <limit effort="300" lower="-2.617993" upper="2.61288" velocity="1"/>
    <dynamics damping="50" friction="1"/>
  </joint>
  <!--
	////////////////////////////////////////////////////////////
	////////////////////////////////////////////////////////////
-->
  <link name="gripper_roll_link">
    <visual>
      <origin rpy="0 1.57079632699 0" xyz="0 0 0"/>
      <geometry>
        <cylinder length="0.02" radius="0.04"/>
      </geometry>
      <material name="Red"/>
    </visual>
    <collision>
      <origin rpy="0 1.57079632699 0" xyz="0 0 0"/>
      <geometry>
        <cylinder length="0.02" radius="0.04"/>
      </geometry>
    </collision>
    <inertial>
      <mass value="1"/>
      <inertia ixx="1.0" ixy="0.0" ixz="0.0" iyy="1.0" iyz="0.0" izz="1.0"/>
    </inertial>
  </link>
  <gazebo reference="gripper_roll_link">
    <material>Gazebo/Red</material>
  </gazebo>
  <!--
	////////////////////////////////////////////////////////////
	////////////////////////////////////////////////////////////
-->
  <joint name="finger_joint1" type="prismatic">
    <parent link="gripper_roll_link"/>
    <child link="gripper_finger_link1"/>
    <origin xyz="0 0 0"/>
    <axis xyz="0 1 0"/>
    <limit effort="300" lower="0" upper="0.03" velocity="1.0"/>
    <safety_controller k_position="20" k_velocity="20" soft_lower_limit="-0.15" soft_upper_limit="0.0"/>
    <dynamics damping="50" friction="1"/>
  </joint>
  <!--
	////////////////////////////////////////////////////////////
	////////////////////////////////////////////////////////////
-->
  <link name="gripper_finger_link1">
    <visual>
      <origin xyz="0.04 -0.03 0"/>
      <geometry>
        <box size="0.08 0.01 0.01"/>
      </geometry>
      <material name="White"/>
    </visual>
    <inertial>
      <mass value="1"/>
      <inertia ixx="1.0" ixy="0.0" ixz="0.0" iyy="1.0" iyz="0.0" izz="1.0"/>
    </inertial>
  </link>
  <gazebo reference="bottom_link">
    <material>Gazebo/White</material>
  </gazebo>
  <!--
	////////////////////////////////////////////////////////////
	////////////////////////////////////////////////////////////
-->
  <joint name="finger_jiont2" type="prismatic">
    <parent link="gripper_roll_link"/>
    <child link="gripper_finger_link2"/>
    <origin xyz="0 0 0"/>
    <axis xyz="0 1 0"/>
    <limit effort="1" lower="-0.03" upper="0" velocity="1.0"/>
    <dynamics damping="50" friction="1"/>
  </joint>
  <!--
	////////////////////////////////////////////////////////////
	////////////////////////////////////////////////////////////
-->
  <link name="gripper_finger_link2">
    <visual>
      <origin xyz="0.04 0.03 0"/>
      <geometry>
        <box size="0.08 0.01 0.01"/>
      </geometry>
      <material name="White"/>
    </visual>
    <inertial>
      <mass value="1"/>
      <inertia ixx="1.0" ixy="0.0" ixz="0.0" iyy="1.0" iyz="0.0" izz="1.0"/>
    </inertial>
  </link>
  <gazebo reference="bottom_link">
    <material>Gazebo/White</material>
  </gazebo>
  <!--
	////////////////////////////////////////////////////////////
	////////////////////////////////////////////////////////////
-->
  <link name="grasping_frame">
    <iertial>
      <origin rpy="0 0 0" xyz="0 0 0"/>
      <mass value="0.0001"/>
      <cuboid_inertia mass="0.0001" x="0.001" y="0.001" z="0.001"/>
      <inertia ixx="1.0" ixy="0.0" ixz="0.0" iyy="100.0" iyz="0.0" izz="1.0"/>
    </iertial>
    <visual>
      <origin xyz="0 0 0"/>
      <geometry>
        <box size="0.02 0.02 0.02"/>
      </geometry>
      <material name="White"/>
    </visual>
  </link>
  <!--
	////////////////////////////////////////////////////////////
	////////////////////////////////////////////////////////////
-->
  <joint name="grasping_frame_joint" type="fixed">
    <parent link="gripper_roll_link"/>
    <child link="grasping_frame"/>
    <origin rpy="0 0 0" xyz="0.08 0 0"/>
  </joint>
  <transmission name="tran1">
    <type>transmission_interface/SimpleTransmission</type>
    <joint name="shoulder_pan_joint">
      <hardwareInterface>PositionJointInterface</hardwareInterface>
    </joint>
    <actuator name="motor1">
      <hardwareInterface>PositionJointInterface</hardwareInterface>
      <mechanicalReduction>1</mechanicalReduction>
    </actuator>
  </transmission>
  <transmission name="tran1">
    <type>transmission_interface/SimpleTransmission</type>
    <joint name="shoulder_pitch_joint">
      <hardwareInterface>PositionJointInterface</hardwareInterface>
    </joint>
    <actuator name="motor1">
      <hardwareInterface>PositionJointInterface</hardwareInterface>
      <mechanicalReduction>1</mechanicalReduction>
    </actuator>
  </transmission>
  <transmission name="tran1">
    <type>transmission_interface/SimpleTransmission</type>
    <joint name="elbow_roll_joint">
      <hardwareInterface>PositionJointInterface</hardwareInterface>
    </joint>
    <actuator name="motor1">
      <hardwareInterface>PositionJointInterface</hardwareInterface>
      <mechanicalReduction>1</mechanicalReduction>
    </actuator>
  </transmission>
  <transmission name="tran1">
    <type>transmission_interface/SimpleTransmission</type>
    <joint name="elbow_pitch_joint">
      <hardwareInterface>PositionJointInterface</hardwareInterface>
    </joint>
    <actuator name="motor1">
      <hardwareInterface>PositionJointInterface</hardwareInterface>
      <mechanicalReduction>1</mechanicalReduction>
    </actuator>
  </transmission>
  <transmission name="tran1">
    <type>transmission_interface/SimpleTransmission</type>
    <joint name="wrist_roll_joint">
      <hardwareInterface>PositionJointInterface</hardwareInterface>
    </joint>
    <actuator name="motor1">
      <hardwareInterface>PositionJointInterface</hardwareInterface>
      <mechanicalReduction>1</mechanicalReduction>
    </actuator>
  </transmission>
  <transmission name="tran1">
    <type>transmission_interface/SimpleTransmission</type>
    <joint name="wrist_pitch_joint">
      <hardwareInterface>PositionJointInterface</hardwareInterface>
    </joint>
    <actuator name="motor1">
      <hardwareInterface>PositionJointInterface</hardwareInterface>
      <mechanicalReduction>1</mechanicalReduction>
    </actuator>
  </transmission>
  <transmission name="tran1">
    <type>transmission_interface/SimpleTransmission</type>
    <joint name="gripper_roll_joint">
      <hardwareInterface>PositionJointInterface</hardwareInterface>
    </joint>
    <actuator name="motor1">
      <hardwareInterface>PositionJointInterface</hardwareInterface>
      <mechanicalReduction>1</mechanicalReduction>
    </actuator>
  </transmission>
  <transmission name="tran1">
    <type>transmission_interface/SimpleTransmission</type>
    <joint name="finger_joint1">
      <hardwareInterface>PositionJointInterface</hardwareInterface>
    </joint>
    <actuator name="motor1">
      <hardwareInterface>PositionJointInterface</hardwareInterface>
      <mechanicalReduction>1</mechanicalReduction>
    </actuator>
  </transmission>
  <transmission name="tran1">
    <type>transmission_interface/SimpleTransmission</type>
    <joint name="finger_joint2">
      <hardwareInterface>PositionJointInterface</hardwareInterface>
    </joint>
    <actuator name="motor1">
      <hardwareInterface>PositionJointInterface</hardwareInterface>
      <mechanicalReduction>1</mechanicalReduction>
    </actuator>
  </transmission>
  <!--
  <xacro:xtion_pro_live name="rgbd_camera" parent="base">
	<origin xyz="0.1 0 1" rpy="0 ${75.0 * deg_to_rad} 0"/>
	<origin xyz="0 0 0" rpy="0 ${-90.0 * deg_to_rad} 0 ${-90 * deg_to_rad}"/>
  </xacro:xtion_pro_live>
  -->
  <gazebo>
    <plugin filename="libgazebo_ros_control.so" name="gazebo_ros_control">
      <robotNamespace>/seven_dof_arm</robotNamespace>
    </plugin>
  </gazebo>
</robot>

